2025-03-17 12:38:24 - INFO - utility.logger - Logging system initialized.
2025-03-17 12:39:04 - INFO - utility.logger - Logging system initialized.
2025-03-17 12:39:45 - INFO - utility.logger - Logging system initialized.
2025-03-17 12:40:03 - INFO - utility.logger - Logging system initialized.
2025-03-17 12:46:18 - INFO - utility.logger - Logging system initialized.
2025-03-17 13:05:02 - INFO - utility.logger - Logging system initialized.
2025-03-17 13:06:00 - INFO - utility.logger - Logging system initialized.
2025-03-17 13:06:26 - INFO - utility.logger - Logging system initialized.
2025-03-17 13:06:36 - INFO - utility.logger - Logging system initialized.
2025-03-17 13:06:48 - INFO - utility.logger - Logging system initialized.
2025-03-17 13:06:48 - INFO - __main__ - Database connection successful.
2025-03-17 13:10:40 - INFO - utility.logger - Logging system initialized.
2025-03-17 13:10:40 - INFO - __main__ - Database connection successful.
2025-03-17 13:12:48 - INFO - utility.logger - Logging system initialized.
2025-03-17 13:12:48 - INFO - __main__ - Database connection successful.
2025-03-17 13:13:13 - INFO - utility.logger - Logging system initialized.
2025-03-17 13:13:13 - INFO - __main__ - Database connection successful.
2025-03-17 13:13:22 - INFO - utility.logger - Logging system initialized.
2025-03-17 13:13:22 - INFO - __main__ - Database connection successful.
2025-03-17 13:13:22 - INFO - MESMain - Initializing MQTT connection...
2025-03-17 13:13:22 - INFO - MESMain - Starting periodic message service...
2025-03-17 13:13:22 - INFO - mqtt.mqtt_message_processor - Started periodic message sending thread.
2025-03-17 13:13:22 - INFO - MESMain - Starting heartbeat monitoring...
2025-03-17 13:13:22 - INFO - mqtt.mqtt_heart_beat - Starting heartbeat monitor thread.
2025-03-17 13:13:22 - INFO - mqtt.mqtt_heart_beat - Heartbeat monitoring started.
2025-03-17 13:13:22 - INFO - MESMain - Starting MQTT client loop...
2025-03-17 13:13:22 - ERROR - service.equipment_service - Error fetching all equipment.
Traceback (most recent call last):
  File "C:\Users\Antonio Melo\AppData\Local\Programs\Python\Python312\Lib\site-packages\sqlalchemy\engine\base.py", line 1964, in _exec_single_context
    self.dialect.do_execute(
  File "C:\Users\Antonio Melo\AppData\Local\Programs\Python\Python312\Lib\site-packages\sqlalchemy\engine\default.py", line 942, in do_execute
    cursor.execute(statement, parameters)
psycopg2.errors.UndefinedTable: relation "equipment" does not exist
LINE 2: FROM equipment
             ^


The above exception was the direct cause of the following exception:

Traceback (most recent call last):
  File "C:\Users\Antonio Melo\Documents\MESCloud\GTW\GTWMES\app\service\equipment_service.py", line 33, in get_all_equipment
    return self.equipment_dao.find_all()
           ^^^^^^^^^^^^^^^^^^^^^^^^^^^^^
  File "C:\Users\Antonio Melo\Documents\MESCloud\GTW\GTWMES\app\database\dao\equipment_dao.py", line 18, in find_all
    return self.session.query(Equipment).all()
           ^^^^^^^^^^^^^^^^^^^^^^^^^^^^^^^^^^^
  File "C:\Users\Antonio Melo\AppData\Local\Programs\Python\Python312\Lib\site-packages\sqlalchemy\orm\query.py", line 2704, in all
    return self._iter().all()  # type: ignore
           ^^^^^^^^^^^^
  File "C:\Users\Antonio Melo\AppData\Local\Programs\Python\Python312\Lib\site-packages\sqlalchemy\orm\query.py", line 2858, in _iter
    result: Union[ScalarResult[_T], Result[_T]] = self.session.execute(
                                                  ^^^^^^^^^^^^^^^^^^^^^
  File "C:\Users\Antonio Melo\AppData\Local\Programs\Python\Python312\Lib\site-packages\sqlalchemy\orm\session.py", line 2365, in execute
    return self._execute_internal(
           ^^^^^^^^^^^^^^^^^^^^^^^
  File "C:\Users\Antonio Melo\AppData\Local\Programs\Python\Python312\Lib\site-packages\sqlalchemy\orm\session.py", line 2251, in _execute_internal
    result: Result[Any] = compile_state_cls.orm_execute_statement(
                          ^^^^^^^^^^^^^^^^^^^^^^^^^^^^^^^^^^^^^^^^
  File "C:\Users\Antonio Melo\AppData\Local\Programs\Python\Python312\Lib\site-packages\sqlalchemy\orm\context.py", line 306, in orm_execute_statement
    result = conn.execute(
             ^^^^^^^^^^^^^
  File "C:\Users\Antonio Melo\AppData\Local\Programs\Python\Python312\Lib\site-packages\sqlalchemy\engine\base.py", line 1416, in execute
    return meth(
           ^^^^^
  File "C:\Users\Antonio Melo\AppData\Local\Programs\Python\Python312\Lib\site-packages\sqlalchemy\sql\elements.py", line 523, in _execute_on_connection
    return connection._execute_clauseelement(
           ^^^^^^^^^^^^^^^^^^^^^^^^^^^^^^^^^^
  File "C:\Users\Antonio Melo\AppData\Local\Programs\Python\Python312\Lib\site-packages\sqlalchemy\engine\base.py", line 1638, in _execute_clauseelement
    ret = self._execute_context(
          ^^^^^^^^^^^^^^^^^^^^^^
  File "C:\Users\Antonio Melo\AppData\Local\Programs\Python\Python312\Lib\site-packages\sqlalchemy\engine\base.py", line 1843, in _execute_context
    return self._exec_single_context(
           ^^^^^^^^^^^^^^^^^^^^^^^^^^
  File "C:\Users\Antonio Melo\AppData\Local\Programs\Python\Python312\Lib\site-packages\sqlalchemy\engine\base.py", line 1983, in _exec_single_context
    self._handle_dbapi_exception(
  File "C:\Users\Antonio Melo\AppData\Local\Programs\Python\Python312\Lib\site-packages\sqlalchemy\engine\base.py", line 2352, in _handle_dbapi_exception
    raise sqlalchemy_exception.with_traceback(exc_info[2]) from e
  File "C:\Users\Antonio Melo\AppData\Local\Programs\Python\Python312\Lib\site-packages\sqlalchemy\engine\base.py", line 1964, in _exec_single_context
    self.dialect.do_execute(
  File "C:\Users\Antonio Melo\AppData\Local\Programs\Python\Python312\Lib\site-packages\sqlalchemy\engine\default.py", line 942, in do_execute
    cursor.execute(statement, parameters)
sqlalchemy.exc.ProgrammingError: (psycopg2.errors.UndefinedTable) relation "equipment" does not exist
LINE 2: FROM equipment
             ^

[SQL: SELECT equipment.id AS equipment_id, equipment.code AS equipment_code, equipment.ip AS equipment_ip, equipment.p_timer_communication_cycle AS equipment_p_timer_communication_cycle, equipment.production_order_code AS equipment_production_order_code 
FROM equipment]
(Background on this error at: https://sqlalche.me/e/20/f405)
2025-03-17 13:13:22 - ERROR - service.equipment_service - Error fetching and refreshing equipment.
Traceback (most recent call last):
  File "C:\Users\Antonio Melo\AppData\Local\Programs\Python\Python312\Lib\site-packages\sqlalchemy\engine\base.py", line 1964, in _exec_single_context
    self.dialect.do_execute(
  File "C:\Users\Antonio Melo\AppData\Local\Programs\Python\Python312\Lib\site-packages\sqlalchemy\engine\default.py", line 942, in do_execute
    cursor.execute(statement, parameters)
psycopg2.errors.InFailedSqlTransaction: current transaction is aborted, commands ignored until end of transaction block


The above exception was the direct cause of the following exception:

Traceback (most recent call last):
  File "C:\Users\Antonio Melo\Documents\MESCloud\GTW\GTWMES\app\service\equipment_service.py", line 87, in get_all_equipment_refreshed
    equipment_list = self.equipment_dao.find_all()
                     ^^^^^^^^^^^^^^^^^^^^^^^^^^^^^
  File "C:\Users\Antonio Melo\Documents\MESCloud\GTW\GTWMES\app\database\dao\equipment_dao.py", line 18, in find_all
    return self.session.query(Equipment).all()
           ^^^^^^^^^^^^^^^^^^^^^^^^^^^^^^^^^^^
  File "C:\Users\Antonio Melo\AppData\Local\Programs\Python\Python312\Lib\site-packages\sqlalchemy\orm\query.py", line 2704, in all
    return self._iter().all()  # type: ignore
           ^^^^^^^^^^^^
  File "C:\Users\Antonio Melo\AppData\Local\Programs\Python\Python312\Lib\site-packages\sqlalchemy\orm\query.py", line 2858, in _iter
    result: Union[ScalarResult[_T], Result[_T]] = self.session.execute(
                                                  ^^^^^^^^^^^^^^^^^^^^^
  File "C:\Users\Antonio Melo\AppData\Local\Programs\Python\Python312\Lib\site-packages\sqlalchemy\orm\session.py", line 2365, in execute
    return self._execute_internal(
           ^^^^^^^^^^^^^^^^^^^^^^^
  File "C:\Users\Antonio Melo\AppData\Local\Programs\Python\Python312\Lib\site-packages\sqlalchemy\orm\session.py", line 2251, in _execute_internal
    result: Result[Any] = compile_state_cls.orm_execute_statement(
                          ^^^^^^^^^^^^^^^^^^^^^^^^^^^^^^^^^^^^^^^^
  File "C:\Users\Antonio Melo\AppData\Local\Programs\Python\Python312\Lib\site-packages\sqlalchemy\orm\context.py", line 306, in orm_execute_statement
    result = conn.execute(
             ^^^^^^^^^^^^^
  File "C:\Users\Antonio Melo\AppData\Local\Programs\Python\Python312\Lib\site-packages\sqlalchemy\engine\base.py", line 1416, in execute
    return meth(
           ^^^^^
  File "C:\Users\Antonio Melo\AppData\Local\Programs\Python\Python312\Lib\site-packages\sqlalchemy\sql\elements.py", line 523, in _execute_on_connection
    return connection._execute_clauseelement(
           ^^^^^^^^^^^^^^^^^^^^^^^^^^^^^^^^^^
  File "C:\Users\Antonio Melo\AppData\Local\Programs\Python\Python312\Lib\site-packages\sqlalchemy\engine\base.py", line 1638, in _execute_clauseelement
    ret = self._execute_context(
          ^^^^^^^^^^^^^^^^^^^^^^
  File "C:\Users\Antonio Melo\AppData\Local\Programs\Python\Python312\Lib\site-packages\sqlalchemy\engine\base.py", line 1843, in _execute_context
    return self._exec_single_context(
           ^^^^^^^^^^^^^^^^^^^^^^^^^^
  File "C:\Users\Antonio Melo\AppData\Local\Programs\Python\Python312\Lib\site-packages\sqlalchemy\engine\base.py", line 1983, in _exec_single_context
    self._handle_dbapi_exception(
  File "C:\Users\Antonio Melo\AppData\Local\Programs\Python\Python312\Lib\site-packages\sqlalchemy\engine\base.py", line 2352, in _handle_dbapi_exception
    raise sqlalchemy_exception.with_traceback(exc_info[2]) from e
  File "C:\Users\Antonio Melo\AppData\Local\Programs\Python\Python312\Lib\site-packages\sqlalchemy\engine\base.py", line 1964, in _exec_single_context
    self.dialect.do_execute(
  File "C:\Users\Antonio Melo\AppData\Local\Programs\Python\Python312\Lib\site-packages\sqlalchemy\engine\default.py", line 942, in do_execute
    cursor.execute(statement, parameters)
sqlalchemy.exc.InternalError: (psycopg2.errors.InFailedSqlTransaction) current transaction is aborted, commands ignored until end of transaction block

[SQL: SELECT equipment.id AS equipment_id, equipment.code AS equipment_code, equipment.ip AS equipment_ip, equipment.p_timer_communication_cycle AS equipment_p_timer_communication_cycle, equipment.production_order_code AS equipment_production_order_code 
FROM equipment]
(Background on this error at: https://sqlalche.me/e/20/2j85)
2025-03-17 13:13:22 - ERROR - service.message_service - Error executing production count: Unable to fetch all equipment.
Traceback (most recent call last):
  File "C:\Users\Antonio Melo\AppData\Local\Programs\Python\Python312\Lib\site-packages\sqlalchemy\engine\base.py", line 1964, in _exec_single_context
    self.dialect.do_execute(
  File "C:\Users\Antonio Melo\AppData\Local\Programs\Python\Python312\Lib\site-packages\sqlalchemy\engine\default.py", line 942, in do_execute
    cursor.execute(statement, parameters)
psycopg2.errors.UndefinedTable: relation "equipment" does not exist
LINE 2: FROM equipment
             ^


The above exception was the direct cause of the following exception:

Traceback (most recent call last):
  File "C:\Users\Antonio Melo\Documents\MESCloud\GTW\GTWMES\app\service\equipment_service.py", line 33, in get_all_equipment
    return self.equipment_dao.find_all()
           ^^^^^^^^^^^^^^^^^^^^^^^^^^^^^
  File "C:\Users\Antonio Melo\Documents\MESCloud\GTW\GTWMES\app\database\dao\equipment_dao.py", line 18, in find_all
    return self.session.query(Equipment).all()
           ^^^^^^^^^^^^^^^^^^^^^^^^^^^^^^^^^^^
  File "C:\Users\Antonio Melo\AppData\Local\Programs\Python\Python312\Lib\site-packages\sqlalchemy\orm\query.py", line 2704, in all
    return self._iter().all()  # type: ignore
           ^^^^^^^^^^^^
  File "C:\Users\Antonio Melo\AppData\Local\Programs\Python\Python312\Lib\site-packages\sqlalchemy\orm\query.py", line 2858, in _iter
    result: Union[ScalarResult[_T], Result[_T]] = self.session.execute(
                                                  ^^^^^^^^^^^^^^^^^^^^^
  File "C:\Users\Antonio Melo\AppData\Local\Programs\Python\Python312\Lib\site-packages\sqlalchemy\orm\session.py", line 2365, in execute
    return self._execute_internal(
           ^^^^^^^^^^^^^^^^^^^^^^^
  File "C:\Users\Antonio Melo\AppData\Local\Programs\Python\Python312\Lib\site-packages\sqlalchemy\orm\session.py", line 2251, in _execute_internal
    result: Result[Any] = compile_state_cls.orm_execute_statement(
                          ^^^^^^^^^^^^^^^^^^^^^^^^^^^^^^^^^^^^^^^^
  File "C:\Users\Antonio Melo\AppData\Local\Programs\Python\Python312\Lib\site-packages\sqlalchemy\orm\context.py", line 306, in orm_execute_statement
    result = conn.execute(
             ^^^^^^^^^^^^^
  File "C:\Users\Antonio Melo\AppData\Local\Programs\Python\Python312\Lib\site-packages\sqlalchemy\engine\base.py", line 1416, in execute
    return meth(
           ^^^^^
  File "C:\Users\Antonio Melo\AppData\Local\Programs\Python\Python312\Lib\site-packages\sqlalchemy\sql\elements.py", line 523, in _execute_on_connection
    return connection._execute_clauseelement(
           ^^^^^^^^^^^^^^^^^^^^^^^^^^^^^^^^^^
  File "C:\Users\Antonio Melo\AppData\Local\Programs\Python\Python312\Lib\site-packages\sqlalchemy\engine\base.py", line 1638, in _execute_clauseelement
    ret = self._execute_context(
          ^^^^^^^^^^^^^^^^^^^^^^
  File "C:\Users\Antonio Melo\AppData\Local\Programs\Python\Python312\Lib\site-packages\sqlalchemy\engine\base.py", line 1843, in _execute_context
    return self._exec_single_context(
           ^^^^^^^^^^^^^^^^^^^^^^^^^^
  File "C:\Users\Antonio Melo\AppData\Local\Programs\Python\Python312\Lib\site-packages\sqlalchemy\engine\base.py", line 1983, in _exec_single_context
    self._handle_dbapi_exception(
  File "C:\Users\Antonio Melo\AppData\Local\Programs\Python\Python312\Lib\site-packages\sqlalchemy\engine\base.py", line 2352, in _handle_dbapi_exception
    raise sqlalchemy_exception.with_traceback(exc_info[2]) from e
  File "C:\Users\Antonio Melo\AppData\Local\Programs\Python\Python312\Lib\site-packages\sqlalchemy\engine\base.py", line 1964, in _exec_single_context
    self.dialect.do_execute(
  File "C:\Users\Antonio Melo\AppData\Local\Programs\Python\Python312\Lib\site-packages\sqlalchemy\engine\default.py", line 942, in do_execute
    cursor.execute(statement, parameters)
sqlalchemy.exc.ProgrammingError: (psycopg2.errors.UndefinedTable) relation "equipment" does not exist
LINE 2: FROM equipment
             ^

[SQL: SELECT equipment.id AS equipment_id, equipment.code AS equipment_code, equipment.ip AS equipment_ip, equipment.p_timer_communication_cycle AS equipment_p_timer_communication_cycle, equipment.production_order_code AS equipment_production_order_code 
FROM equipment]
(Background on this error at: https://sqlalche.me/e/20/f405)

The above exception was the direct cause of the following exception:

Traceback (most recent call last):
  File "C:\Users\Antonio Melo\Documents\MESCloud\GTW\GTWMES\app\service\message_service.py", line 30, in execute_production_count
    equipments = self.equipment_service.get_all_equipment()
                 ^^^^^^^^^^^^^^^^^^^^^^^^^^^^^^^^^^^^^^^^^^
  File "C:\Users\Antonio Melo\Documents\MESCloud\GTW\GTWMES\app\service\equipment_service.py", line 36, in get_all_equipment
    raise ServiceException("Unable to fetch all equipment.") from e
exception.Exception.ServiceException: Unable to fetch all equipment.
2025-03-17 13:13:22 - ERROR - mqtt.mqtt_heart_beat - Unexpected error in heartbeat monitor: Unable to fetch and refresh equipment.
Traceback (most recent call last):
  File "C:\Users\Antonio Melo\AppData\Local\Programs\Python\Python312\Lib\site-packages\sqlalchemy\engine\base.py", line 1964, in _exec_single_context
    self.dialect.do_execute(
  File "C:\Users\Antonio Melo\AppData\Local\Programs\Python\Python312\Lib\site-packages\sqlalchemy\engine\default.py", line 942, in do_execute
    cursor.execute(statement, parameters)
psycopg2.errors.InFailedSqlTransaction: current transaction is aborted, commands ignored until end of transaction block


The above exception was the direct cause of the following exception:

Traceback (most recent call last):
  File "C:\Users\Antonio Melo\Documents\MESCloud\GTW\GTWMES\app\service\equipment_service.py", line 87, in get_all_equipment_refreshed
    equipment_list = self.equipment_dao.find_all()
                     ^^^^^^^^^^^^^^^^^^^^^^^^^^^^^
  File "C:\Users\Antonio Melo\Documents\MESCloud\GTW\GTWMES\app\database\dao\equipment_dao.py", line 18, in find_all
    return self.session.query(Equipment).all()
           ^^^^^^^^^^^^^^^^^^^^^^^^^^^^^^^^^^^
  File "C:\Users\Antonio Melo\AppData\Local\Programs\Python\Python312\Lib\site-packages\sqlalchemy\orm\query.py", line 2704, in all
    return self._iter().all()  # type: ignore
           ^^^^^^^^^^^^
  File "C:\Users\Antonio Melo\AppData\Local\Programs\Python\Python312\Lib\site-packages\sqlalchemy\orm\query.py", line 2858, in _iter
    result: Union[ScalarResult[_T], Result[_T]] = self.session.execute(
                                                  ^^^^^^^^^^^^^^^^^^^^^
  File "C:\Users\Antonio Melo\AppData\Local\Programs\Python\Python312\Lib\site-packages\sqlalchemy\orm\session.py", line 2365, in execute
    return self._execute_internal(
           ^^^^^^^^^^^^^^^^^^^^^^^
  File "C:\Users\Antonio Melo\AppData\Local\Programs\Python\Python312\Lib\site-packages\sqlalchemy\orm\session.py", line 2251, in _execute_internal
    result: Result[Any] = compile_state_cls.orm_execute_statement(
                          ^^^^^^^^^^^^^^^^^^^^^^^^^^^^^^^^^^^^^^^^
  File "C:\Users\Antonio Melo\AppData\Local\Programs\Python\Python312\Lib\site-packages\sqlalchemy\orm\context.py", line 306, in orm_execute_statement
    result = conn.execute(
             ^^^^^^^^^^^^^
  File "C:\Users\Antonio Melo\AppData\Local\Programs\Python\Python312\Lib\site-packages\sqlalchemy\engine\base.py", line 1416, in execute
    return meth(
           ^^^^^
  File "C:\Users\Antonio Melo\AppData\Local\Programs\Python\Python312\Lib\site-packages\sqlalchemy\sql\elements.py", line 523, in _execute_on_connection
    return connection._execute_clauseelement(
           ^^^^^^^^^^^^^^^^^^^^^^^^^^^^^^^^^^
  File "C:\Users\Antonio Melo\AppData\Local\Programs\Python\Python312\Lib\site-packages\sqlalchemy\engine\base.py", line 1638, in _execute_clauseelement
    ret = self._execute_context(
          ^^^^^^^^^^^^^^^^^^^^^^
  File "C:\Users\Antonio Melo\AppData\Local\Programs\Python\Python312\Lib\site-packages\sqlalchemy\engine\base.py", line 1843, in _execute_context
    return self._exec_single_context(
           ^^^^^^^^^^^^^^^^^^^^^^^^^^
  File "C:\Users\Antonio Melo\AppData\Local\Programs\Python\Python312\Lib\site-packages\sqlalchemy\engine\base.py", line 1983, in _exec_single_context
    self._handle_dbapi_exception(
  File "C:\Users\Antonio Melo\AppData\Local\Programs\Python\Python312\Lib\site-packages\sqlalchemy\engine\base.py", line 2352, in _handle_dbapi_exception
    raise sqlalchemy_exception.with_traceback(exc_info[2]) from e
  File "C:\Users\Antonio Melo\AppData\Local\Programs\Python\Python312\Lib\site-packages\sqlalchemy\engine\base.py", line 1964, in _exec_single_context
    self.dialect.do_execute(
  File "C:\Users\Antonio Melo\AppData\Local\Programs\Python\Python312\Lib\site-packages\sqlalchemy\engine\default.py", line 942, in do_execute
    cursor.execute(statement, parameters)
sqlalchemy.exc.InternalError: (psycopg2.errors.InFailedSqlTransaction) current transaction is aborted, commands ignored until end of transaction block

[SQL: SELECT equipment.id AS equipment_id, equipment.code AS equipment_code, equipment.ip AS equipment_ip, equipment.p_timer_communication_cycle AS equipment_p_timer_communication_cycle, equipment.production_order_code AS equipment_production_order_code 
FROM equipment]
(Background on this error at: https://sqlalche.me/e/20/2j85)

The above exception was the direct cause of the following exception:

Traceback (most recent call last):
  File "C:\Users\Antonio Melo\Documents\MESCloud\GTW\GTWMES\app\mqtt\mqtt_heart_beat.py", line 57, in monitor
    equipments = self.equipment_service.get_all_equipment_refreshed()
                 ^^^^^^^^^^^^^^^^^^^^^^^^^^^^^^^^^^^^^^^^^^^^^^^^^^^^
  File "C:\Users\Antonio Melo\Documents\MESCloud\GTW\GTWMES\app\service\equipment_service.py", line 96, in get_all_equipment_refreshed
    raise ServiceException("Unable to fetch and refresh equipment.") from e
exception.Exception.ServiceException: Unable to fetch and refresh equipment.
2025-03-17 13:16:18 - INFO - utility.logger - Logging system initialized.
2025-03-17 13:16:19 - INFO - __main__ - Database connection successful.
2025-03-17 13:16:19 - INFO - MESMain - Initializing MQTT connection...
2025-03-17 13:16:19 - INFO - MESMain - Starting periodic message service...
2025-03-17 13:16:19 - INFO - mqtt.mqtt_message_processor - Started periodic message sending thread.
2025-03-17 13:16:19 - INFO - MESMain - Starting heartbeat monitoring...
2025-03-17 13:16:19 - INFO - mqtt.mqtt_heart_beat - Starting heartbeat monitor thread.
2025-03-17 13:16:19 - WARNING - service.equipment_service - Unable to fetch equipment due to database error: (psycopg2.errors.UndefinedTable) relation "equipment" does not exist
LINE 2: FROM equipment
             ^

[SQL: SELECT equipment.id AS equipment_id, equipment.code AS equipment_code, equipment.ip AS equipment_ip, equipment.p_timer_communication_cycle AS equipment_p_timer_communication_cycle, equipment.production_order_code AS equipment_production_order_code 
FROM equipment]
(Background on this error at: https://sqlalche.me/e/20/f405)
2025-03-17 13:16:19 - INFO - mqtt.mqtt_heart_beat - Heartbeat monitoring started.
2025-03-17 13:16:19 - WARNING - service.message_service - No equipment found for production count execution.
2025-03-17 13:16:19 - INFO - MESMain - Starting MQTT client loop...
2025-03-17 13:16:19 - ERROR - service.equipment_service - Error fetching and refreshing equipment: (psycopg2.errors.InFailedSqlTransaction) current transaction is aborted, commands ignored until end of transaction block

[SQL: SELECT equipment.id AS equipment_id, equipment.code AS equipment_code, equipment.ip AS equipment_ip, equipment.p_timer_communication_cycle AS equipment_p_timer_communication_cycle, equipment.production_order_code AS equipment_production_order_code 
FROM equipment]
(Background on this error at: https://sqlalche.me/e/20/2j85)
Traceback (most recent call last):
  File "C:\Users\Antonio Melo\AppData\Local\Programs\Python\Python312\Lib\site-packages\sqlalchemy\engine\base.py", line 1964, in _exec_single_context
    self.dialect.do_execute(
  File "C:\Users\Antonio Melo\AppData\Local\Programs\Python\Python312\Lib\site-packages\sqlalchemy\engine\default.py", line 942, in do_execute
    cursor.execute(statement, parameters)
psycopg2.errors.InFailedSqlTransaction: current transaction is aborted, commands ignored until end of transaction block


The above exception was the direct cause of the following exception:

Traceback (most recent call last):
  File "C:\Users\Antonio Melo\Documents\MESCloud\GTW\GTWMES\app\service\equipment_service.py", line 90, in get_all_equipment_refreshed
    return self.equipment_dao.find_all()
           ^^^^^^^^^^^^^^^^^^^^^^^^^^^^^
  File "C:\Users\Antonio Melo\Documents\MESCloud\GTW\GTWMES\app\database\dao\equipment_dao.py", line 18, in find_all
    return self.session.query(Equipment).all()
           ^^^^^^^^^^^^^^^^^^^^^^^^^^^^^^^^^^^
  File "C:\Users\Antonio Melo\AppData\Local\Programs\Python\Python312\Lib\site-packages\sqlalchemy\orm\query.py", line 2704, in all
    return self._iter().all()  # type: ignore
           ^^^^^^^^^^^^
  File "C:\Users\Antonio Melo\AppData\Local\Programs\Python\Python312\Lib\site-packages\sqlalchemy\orm\query.py", line 2858, in _iter
    result: Union[ScalarResult[_T], Result[_T]] = self.session.execute(
                                                  ^^^^^^^^^^^^^^^^^^^^^
  File "C:\Users\Antonio Melo\AppData\Local\Programs\Python\Python312\Lib\site-packages\sqlalchemy\orm\session.py", line 2365, in execute
    return self._execute_internal(
           ^^^^^^^^^^^^^^^^^^^^^^^
  File "C:\Users\Antonio Melo\AppData\Local\Programs\Python\Python312\Lib\site-packages\sqlalchemy\orm\session.py", line 2251, in _execute_internal
    result: Result[Any] = compile_state_cls.orm_execute_statement(
                          ^^^^^^^^^^^^^^^^^^^^^^^^^^^^^^^^^^^^^^^^
  File "C:\Users\Antonio Melo\AppData\Local\Programs\Python\Python312\Lib\site-packages\sqlalchemy\orm\context.py", line 306, in orm_execute_statement
    result = conn.execute(
             ^^^^^^^^^^^^^
  File "C:\Users\Antonio Melo\AppData\Local\Programs\Python\Python312\Lib\site-packages\sqlalchemy\engine\base.py", line 1416, in execute
    return meth(
           ^^^^^
  File "C:\Users\Antonio Melo\AppData\Local\Programs\Python\Python312\Lib\site-packages\sqlalchemy\sql\elements.py", line 523, in _execute_on_connection
    return connection._execute_clauseelement(
           ^^^^^^^^^^^^^^^^^^^^^^^^^^^^^^^^^^
  File "C:\Users\Antonio Melo\AppData\Local\Programs\Python\Python312\Lib\site-packages\sqlalchemy\engine\base.py", line 1638, in _execute_clauseelement
    ret = self._execute_context(
          ^^^^^^^^^^^^^^^^^^^^^^
  File "C:\Users\Antonio Melo\AppData\Local\Programs\Python\Python312\Lib\site-packages\sqlalchemy\engine\base.py", line 1843, in _execute_context
    return self._exec_single_context(
           ^^^^^^^^^^^^^^^^^^^^^^^^^^
  File "C:\Users\Antonio Melo\AppData\Local\Programs\Python\Python312\Lib\site-packages\sqlalchemy\engine\base.py", line 1983, in _exec_single_context
    self._handle_dbapi_exception(
  File "C:\Users\Antonio Melo\AppData\Local\Programs\Python\Python312\Lib\site-packages\sqlalchemy\engine\base.py", line 2352, in _handle_dbapi_exception
    raise sqlalchemy_exception.with_traceback(exc_info[2]) from e
  File "C:\Users\Antonio Melo\AppData\Local\Programs\Python\Python312\Lib\site-packages\sqlalchemy\engine\base.py", line 1964, in _exec_single_context
    self.dialect.do_execute(
  File "C:\Users\Antonio Melo\AppData\Local\Programs\Python\Python312\Lib\site-packages\sqlalchemy\engine\default.py", line 942, in do_execute
    cursor.execute(statement, parameters)
sqlalchemy.exc.InternalError: (psycopg2.errors.InFailedSqlTransaction) current transaction is aborted, commands ignored until end of transaction block

[SQL: SELECT equipment.id AS equipment_id, equipment.code AS equipment_code, equipment.ip AS equipment_ip, equipment.p_timer_communication_cycle AS equipment_p_timer_communication_cycle, equipment.production_order_code AS equipment_production_order_code 
FROM equipment]
(Background on this error at: https://sqlalche.me/e/20/2j85)
2025-03-17 13:16:19 - ERROR - mqtt.mqtt_heart_beat - Unexpected error in heartbeat monitor: Unable to fetch and refresh equipment.
Traceback (most recent call last):
  File "C:\Users\Antonio Melo\AppData\Local\Programs\Python\Python312\Lib\site-packages\sqlalchemy\engine\base.py", line 1964, in _exec_single_context
    self.dialect.do_execute(
  File "C:\Users\Antonio Melo\AppData\Local\Programs\Python\Python312\Lib\site-packages\sqlalchemy\engine\default.py", line 942, in do_execute
    cursor.execute(statement, parameters)
psycopg2.errors.InFailedSqlTransaction: current transaction is aborted, commands ignored until end of transaction block


The above exception was the direct cause of the following exception:

Traceback (most recent call last):
  File "C:\Users\Antonio Melo\Documents\MESCloud\GTW\GTWMES\app\service\equipment_service.py", line 90, in get_all_equipment_refreshed
    return self.equipment_dao.find_all()
           ^^^^^^^^^^^^^^^^^^^^^^^^^^^^^
  File "C:\Users\Antonio Melo\Documents\MESCloud\GTW\GTWMES\app\database\dao\equipment_dao.py", line 18, in find_all
    return self.session.query(Equipment).all()
           ^^^^^^^^^^^^^^^^^^^^^^^^^^^^^^^^^^^
  File "C:\Users\Antonio Melo\AppData\Local\Programs\Python\Python312\Lib\site-packages\sqlalchemy\orm\query.py", line 2704, in all
    return self._iter().all()  # type: ignore
           ^^^^^^^^^^^^
  File "C:\Users\Antonio Melo\AppData\Local\Programs\Python\Python312\Lib\site-packages\sqlalchemy\orm\query.py", line 2858, in _iter
    result: Union[ScalarResult[_T], Result[_T]] = self.session.execute(
                                                  ^^^^^^^^^^^^^^^^^^^^^
  File "C:\Users\Antonio Melo\AppData\Local\Programs\Python\Python312\Lib\site-packages\sqlalchemy\orm\session.py", line 2365, in execute
    return self._execute_internal(
           ^^^^^^^^^^^^^^^^^^^^^^^
  File "C:\Users\Antonio Melo\AppData\Local\Programs\Python\Python312\Lib\site-packages\sqlalchemy\orm\session.py", line 2251, in _execute_internal
    result: Result[Any] = compile_state_cls.orm_execute_statement(
                          ^^^^^^^^^^^^^^^^^^^^^^^^^^^^^^^^^^^^^^^^
  File "C:\Users\Antonio Melo\AppData\Local\Programs\Python\Python312\Lib\site-packages\sqlalchemy\orm\context.py", line 306, in orm_execute_statement
    result = conn.execute(
             ^^^^^^^^^^^^^
  File "C:\Users\Antonio Melo\AppData\Local\Programs\Python\Python312\Lib\site-packages\sqlalchemy\engine\base.py", line 1416, in execute
    return meth(
           ^^^^^
  File "C:\Users\Antonio Melo\AppData\Local\Programs\Python\Python312\Lib\site-packages\sqlalchemy\sql\elements.py", line 523, in _execute_on_connection
    return connection._execute_clauseelement(
           ^^^^^^^^^^^^^^^^^^^^^^^^^^^^^^^^^^
  File "C:\Users\Antonio Melo\AppData\Local\Programs\Python\Python312\Lib\site-packages\sqlalchemy\engine\base.py", line 1638, in _execute_clauseelement
    ret = self._execute_context(
          ^^^^^^^^^^^^^^^^^^^^^^
  File "C:\Users\Antonio Melo\AppData\Local\Programs\Python\Python312\Lib\site-packages\sqlalchemy\engine\base.py", line 1843, in _execute_context
    return self._exec_single_context(
           ^^^^^^^^^^^^^^^^^^^^^^^^^^
  File "C:\Users\Antonio Melo\AppData\Local\Programs\Python\Python312\Lib\site-packages\sqlalchemy\engine\base.py", line 1983, in _exec_single_context
    self._handle_dbapi_exception(
  File "C:\Users\Antonio Melo\AppData\Local\Programs\Python\Python312\Lib\site-packages\sqlalchemy\engine\base.py", line 2352, in _handle_dbapi_exception
    raise sqlalchemy_exception.with_traceback(exc_info[2]) from e
  File "C:\Users\Antonio Melo\AppData\Local\Programs\Python\Python312\Lib\site-packages\sqlalchemy\engine\base.py", line 1964, in _exec_single_context
    self.dialect.do_execute(
  File "C:\Users\Antonio Melo\AppData\Local\Programs\Python\Python312\Lib\site-packages\sqlalchemy\engine\default.py", line 942, in do_execute
    cursor.execute(statement, parameters)
sqlalchemy.exc.InternalError: (psycopg2.errors.InFailedSqlTransaction) current transaction is aborted, commands ignored until end of transaction block

[SQL: SELECT equipment.id AS equipment_id, equipment.code AS equipment_code, equipment.ip AS equipment_ip, equipment.p_timer_communication_cycle AS equipment_p_timer_communication_cycle, equipment.production_order_code AS equipment_production_order_code 
FROM equipment]
(Background on this error at: https://sqlalche.me/e/20/2j85)

The above exception was the direct cause of the following exception:

Traceback (most recent call last):
  File "C:\Users\Antonio Melo\Documents\MESCloud\GTW\GTWMES\app\mqtt\mqtt_heart_beat.py", line 57, in monitor
    equipments = self.equipment_service.get_all_equipment_refreshed()
                 ^^^^^^^^^^^^^^^^^^^^^^^^^^^^^^^^^^^^^^^^^^^^^^^^^^^^
  File "C:\Users\Antonio Melo\Documents\MESCloud\GTW\GTWMES\app\service\equipment_service.py", line 96, in get_all_equipment_refreshed
    raise ServiceException("Unable to fetch and refresh equipment.") from e
exception.Exception.ServiceException: Unable to fetch and refresh equipment.
2025-03-17 13:40:09 - INFO - utility.logger - Logging system initialized.
2025-03-17 13:40:09 - INFO - __main__ - Database connection successful.
2025-03-17 13:40:09 - INFO - MESMain - Initializing MQTT connection...
2025-03-17 13:40:09 - INFO - MESMain - Starting periodic message service...
2025-03-17 13:40:09 - INFO - mqtt.mqtt_message_processor - Started periodic message sending thread.
2025-03-17 13:40:09 - INFO - MESMain - Starting heartbeat monitoring...
2025-03-17 13:40:09 - INFO - mqtt.mqtt_heart_beat - Starting heartbeat monitor thread.
2025-03-17 13:40:09 - INFO - mqtt.mqtt_heart_beat - Heartbeat monitoring started.
2025-03-17 13:40:09 - INFO - MESMain - Starting MQTT client loop...
2025-03-17 13:40:09 - WARNING - service.message_service - No equipment found for production count execution.
